Workbook

Sheet Data_Transactions
A1: order_id | B1: order_date | C1: quarter | D1: rep_name | E1: region | F1: segment | G1: channel_partner | H1: product_category | I1: product_name | J1: quantity | K1: unit_list_price | L1: list_revenue | M1: discount_rate | N1: discount_amount | O1: net_revenue | P1: cogs | Q1: gross_profit | R1: gross_margin_pct | S1: plan_discount_rate | T1: discount_variance_vs_plan
A2: ORD-10000 | B2: 2023-06-28 | C2: Q2 2023 | D2: Carlos Rivera | E2: Central | F2: Enterprise | G2: Trace3 | H2: GPUs | I2: Instinct MI300X | J2: 15 | K2: 16800.94 | L2: 252014.1 | M2: 0.0852 | N2: 21471.6 | O2: 230542.5 | P2: 156248.74 | Q2: 74293.76 | R2: 0.3223 | S2: 0.0832 | T2: 0.002
A3: ORD-10001 | B3: 2025-05-09 | C3: Q2 2025 | D3: Jordan Mitchell | E3: West | F3: Enterprise | G3: Ingram Micro | H3: GPUs | I3: Instinct MI300X | J3: 39 | K3: 15445.15 | L3: 602360.85 | M3: 0.1332 | N3: 80234.47 | O3: 522126.38 | P3: 373463.73 | Q3: 148662.65 | R3: 0.2847 | S3: 0.1154 | T3: 0.0178
A4: ORD-10002 | B4: 2024-11-20 | C4: Q4 2024 | D4: Mei-Lin Park | E4: East | F4: SMB | G4: TD Synnex | H4: Embedded | I4: Versal AI Core | J4: 22 | K4: 2943.49 | L4: 64756.78 | M4: 0.0725 | N4: 4694.87 | O4: 60061.91 | P4: 35616.23 | Q4: 24445.68 | R4: 0.407 | S4: 0.0602 | T4: 0.0123
A5: ORD-10003 | B5: 2025-02-14 | C5: Q1 2025 | D5: Kenji Tanaka | E5: South | F5: Enterprise | G5: Insight Direct | H5: GPUs | I5: Radeon RX 7900 | J5: 3 | K5: 27319.23 | L5: 81957.69 | M5: 0.1494 | N5: 12244.48 | O5: 69713.21 | P5: 50813.77 | Q5: 18899.44 | R5: 0.2711 | S5: 0.123 | T5: 0.0264
A6: ORD-10004 | B6: 2024-04-11 | C6: Q2 2024 | D6: Tyler Brooks | E6: Central | F6: SMB | G6: Presidio | H6: Adaptive Computing | I6: Alveo U250 | J6: 5 | K6: 5076.62 | L6: 25383.1 | M6: 0.0323 | N6: 819.87 | O6: 24563.23 | P6: 15229.86 | Q6: 9333.37 | R6: 0.38 | S6: 0.0333 | T6: -0.001
A7: ORD-10005 | B7: 2023-11-30 | C7: Q4 2023 | D7: Priya Nair | E7: West | F7: Commercial | G7: SHI International | H7: CPUs | I7: EPYC Genoa 9654 | J7: 41 | K7: 5501.76 | L7: 225572.16 | M7: 0.0717 | N7: 16173.52 | O7: 209398.64 | P7: 130831.85 | Q7: 78566.79 | R7: 0.3752 | S7: 0.0653 | T7: 0.0064
A8: ORD-10006 | B8: 2025-12-29 | C8: Q4 2025 | D8: Sofia Delgado | E8: East | F8: Public Sector | G8: World Wide Technology | H8: Embedded | I8: Kria K26 SOM | J8: 39 | K8: 2768.12 | L8: 107956.68 | M8: 0.0617 | N8: 6660.93 | O8: 101295.75 | P8: 59376.17 | Q8: 41919.58 | R8: 0.4138 | S8: 0.0629 | T8: -0.0012
A9: ORD-10007 | B9: 2024-10-26 | C9: Q4 2024 | D9: Marcus Chen | E9: East | F9: Enterprise | G9: CDW | H9: Semi-Custom | I9: PlayStation Custom APU | J9: 41 | K9: 5949.71 | L9: 243938.11 | M9: 0.122 | N9: 29760.45 | O9: 214177.66 | P9: 165877.91 | Q9: 48299.75 | R9: 0.2255 | S9: 0.1284 | T9: -0.0064
A10: ORD-10008 | B10: 2024-10-06 | C10: Q4 2024 | D10: Jordan Mitchell | E10: West | F10: Enterprise | G10: Insight Direct | H10: CPUs | I10: EPYC Genoa 9654 | J10: 5 | K10: 6610.48 | L10: 33052.4 | M10: 0.156 | N10: 5156.17 | O10: 27896.23 | P10: 19170.39 | Q10: 8725.84 | R10: 0.3128 | S10: 0.1347 | T10: 0.0213
A11: ORD-10009 | B11: 2024-06-22 | C11: Q2 2024 | D11: Rachel Okafor | E11: South | F11: Commercial | G11: Connection | H11: Semi-Custom | I11: Steam Deck APU | J11: 9 | K11: 1885.78 | L11: 16972.02 | M11: 0.0423 | N11: 717.92 | O11: 16254.1 | P11: 11540.97 | Q11: 4713.13 | R11: 0.29 | S11: 0.0434 | T11: -0.0011
A12: ORD-10010 | B12: 2023-04-07 | C12: Q2 2023 | D12: Kenji Tanaka | E12: South | F12: Enterprise | G12: Insight Direct | H12: Adaptive Computing | I12: Alveo U250 | J12: 9 | K12: 5509.13 | L12: 49582.17 | M12: 0.1027 | N12: 5092.09 | O12: 44490.08 | P12: 29749.3 | Q12: 14740.78 | R12: 0.3313 | S12: 0.1087 | T12: -0.006
A13: ORD-10011 | B13: 2024-05-29 | C13: Q2 2024 | D13: Marcus Chen | E13: East | F13: Enterprise | G13: Presidio | H13: CPUs | I13: Ryzen Threadripper PRO | J13: 25 | K13: 3571.75 | L13: 89293.75 | M13: 0.1372 | N13: 12251.1 | O13: 77042.65 | P13: 51790.38 | Q13: 25252.27 | R13: 0.3278 | S13: 0.1498 | T13: -0.0126
... A4801: ORD-14799 | B4801: 2024-05-11 | C4801: Q2 2024 | D4801: Jordan Mitchell | E4801: West | F4801: Enterprise | G4801: Connection | H4801: Embedded | I4801: Versal Premium | J4801: 4 | K4801: 3592.52 | L4801: 14370.08 | M4801: 0.1775 | N4801: 2550.69 | O4801: 11819.39 | P4801: 7903.54 | Q4801: 3915.85 | R4801: 0.3313 | S4801: 0.1451 | T4801: 0.0324

Sheet Data_Deals
A1: deal_id | B1: created_date | C1: expected_close_date | D1: rep_name | E1: region | F1: segment | G1: channel_partner | H1: product_category | I1: product_name | J1: deal_stage | K1: deal_size_list | L1: discount_rate | M1: net_deal_value | N1: gross_margin | O1: gm_pct | P1: win_probability | Q1: weighted_pipeline_value | R1: sales_cycle_days | S1: strategic_score | T1: risk_score | U1: loss_reason | V1: composite_score | W1: recommendation
A2: DEAL-5000 | B2: 2025-04-12 | C2: 2025-09-27 | D2: Priya Nair | E2: West | F2: Commercial | G2: TD Synnex | H2: Semi-Custom | I2: Steam Deck APU | J2: Qualified | K2: 1463150.1 | L2: 0.2165 | M2: 1146378.1 | N2: 410484.98 | O2: 0.3581 | P2: 0.244 | Q2: 279716.26 | R2: 168 | S2: 3 | T2: 1.4 | V2: 5.54 | W2: Escalate
A3: DEAL-5001 | B3: 2024-09-21 | C3: 2024-12-09 | D3: Jordan Mitchell | E3: West | F3: Enterprise | G3: CDW | H3: Adaptive Computing | I3: Alveo U55C | J3: Negotiation | K3: 71703.68 | L3: 0.1865 | M3: 58330.94 | N3: 18079.96 | O3: 0.31 | P3: 0.741 | Q3: 43223.23 | R3: 79 | S3: 9.9 | T3: 6 | V3: 6.44 | W3: Escalate
A4: DEAL-5002 | B4: 2025-12-09 | C4: 2026-04-19 | D4: Jordan Mitchell | E4: West | F4: Enterprise | G4: Ingram Micro | H4: Embedded | I4: Kria K26 SOM | J4: Qualified | K4: 2111562.3 | L4: 0.249 | M4: 1585783.3 | N4: 590169.49 | O4: 0.3722 | P4: 0.292 | Q4: 463048.71 | R4: 131 | S4: 6.7 | T4: 4.5 | V4: 5.83 | W4: Escalate
A5: DEAL-5003 | B5: 2025-02-28 | C5: 2025-05-29 | D5: Marcus Chen | E5: East | F5: Enterprise | G5: Avnet | H5: GPUs | I5: Instinct MI250 | J5: Closed Won | K5: 2546553.6 | L5: 0.0574 | M5: 2400381.4 | N5: 814577.72 | O5: 0.3394 | P5: 0.956 | Q5: 2294764.7 | R5: 90 | S5: 9.3 | T5: 6.5 | V5: 7.5 | W5: Approve
A6: DEAL-5004 | B6: 2024-01-09 | C6: 2024-03-17 | D6: Mei-Lin Park | E6: East | F6: SMB | G6: World Wide Technology | H6: Semi-Custom | I6: Steam Deck APU | J6: Proposal | K6: 3219709.1 | L6: 0.1828 | M6: 2631146.3 | N6: 881539.77 | O6: 0.335 | P6: 0.445 | Q6: 1170860.1 | R6: 68 | S6: 2.6 | T6: 9.8 | V6: 4.25 | W6: Reject
A7: DEAL-5005 | B7: 2024-01-24 | C7: 2024-04-20 | D7: Aisha Johnson | E7: Central | F7: Commercial | G7: Avnet | H7: CPUs | I7: Ryzen Threadripper PRO | J7: Qualified | K7: 3688016.5 | L7: 0.2686 | M7: 2697415.3 | N7: 1010180.4 | O7: 0.3745 | P7: 0.299 | Q7: 806527.17 | R7: 87 | S7: 1.7 | T7: 8.1 | V7: 3.87 | W7: Reject
A8: DEAL-5006 | B8: 2024-10-17 | C8: 2024-12-12 | D8: Aisha Johnson | E8: Central | F8: Commercial | G8: World Wide Technology | H8: Semi-Custom | I8: Steam Deck APU | J8: Prospect | K8: 3177113.5 | L8: 0.1599 | M8: 2669093 | N8: 899801.79 | O8: 0.3371 | P8: 0.147 | Q8: 392356.67 | R8: 56 | S8: 2.1 | T8: 5.3 | V8: 5.03 | W8: Escalate
A9: DEAL-5007 | B9: 2024-07-20 | C9: 2024-08-31 | D9: Aisha Johnson | E9: Central | F9: Commercial | G9: CDW | H9: Semi-Custom | I9: Xbox Custom APU | J9: Proposal | K9: 3031329.7 | L9: 0.2914 | M9: 2148000.2 | N9: 922767.49 | O9: 0.4296 | P9: 0.45 | Q9: 966600.09 | R9: 42 | S9: 5.9 | T9: 5 | V9: 5.62 | W9: Escalate
A10: DEAL-5008 | B10: 2024-11-12 | C10: 2024-11-29 | D10: Natalie Frost | E10: South | F10: SMB | G10: World Wide Technology | H10: GPUs | I10: Radeon RX 7900 | J10: Closed Won | K10: 2414083.9 | L10: 0.1587 | M10: 2030968.8 | N10: 961856.22 | O10: 0.4736 | P10: 1 | Q10: 2030968.8 | R10: 17 | S10: 5 | T10: 3.5 | V10: 6.9 | W10: Approve
A11: DEAL-5009 | B11: 2024-04-29 | C11: 2024-10-13 | D11: Kenji Tanaka | E11: South | F11: Enterprise | G11: Avnet | H11: Embedded | I11: Versal AI Core | J11: Proposal | K11: 2272652.9 | L11: 0.1516 | M11: 1928118.7 | N11: 776571 | O11: 0.4028 | P11: 0.461 | Q11: 888862.72 | R11: 167 | S11: 5.4 | T11: 7 | V11: 6.17 | W11: Escalate
A12: DEAL-5010 | B12: 2024-12-08 | C12: 2025-05-14 | D12: Kenji Tanaka | E12: South | F12: Enterprise | G12: TD Synnex | H12: Embedded | I12: Kria K26 SOM | J12: Proposal | K12: 1750834.3 | L12: 0.2635 | M12: 1289489.4 | N12: 580350.46 | O12: 0.4501 | P12: 0.479 | Q12: 617665.45 | R12: 157 | S12: 4.6 | T12: 2.6 | V12: 6.06 | W12: Escalate
A13: DEAL-5011 | B13: 2025-09-22 | C13: 2025-12-14 | D13: Marcus Chen | E13: East | F13: Enterprise | G13: Arrow Electronics | H13: Adaptive Computing | I13: Alveo V80 | J13: Closed Lost | K13: 851985.2 | L13: 0.2957 | M13: 600053.18 | N13: 237618.24 | O13: 0.396 | P13: 0 | Q13: 0 | R13: 83 | S13: 7 | T13: 1.9 | U13: Budget cut | V13: 6.07 | W13: Escalate
A14: DEAL-5012 | B14: 2025-06-22 | C14: 2025-08-30 | D14: Priya Nair | E14: West | F14: Commercial | G14: Connection | H14: CPUs | I14: EPYC Bergamo 9754 | J14: Closed Won | K14: 4642691.5 | L14: 0.1893 | M14: 3763830 | N14: 1301592.9 | O14: 0.3458 | P14: 1 | Q14: 3763830 | R14: 69 | S14: 6.5 | T14: 8.2 | V14: 5.52 | W14: Escalate
A15: DEAL-5013 | B15: 2025-05-28 | C15: 2025-09-26 | D15: Derek Walsh | E15: West | F15: Public Sector | G15: SHI International | H15: Adaptive Computing | I15: Alveo V80 | J15: Qualified | K15: 1822850 | L15: 0.2703 | M15: 1330133.6 | N15: 525880.15 | O15: 0.3954 | P15: 0.219 | Q15: 291299.27 | R15: 121 | S15: 4.7 | T15: 4.9 | V15: 5.27 | W15: Escalate
A16: DEAL-5014 | B16: 2024-11-15 | C16: 2025-01-19 | D16: Priya Nair | E16: West | F16: Commercial | G16: Insight Direct | H16: GPUs | I16: Instinct MI250 | J16: Proposal | K16: 2511326.2 | L16: 0.2104 | M16: 1982943.1 | N16: 931267.14 | O16: 0.4696 | P16: 0.449 | Q16: 890341.47 | R16: 65 | S16: 9.3 | T16: 7.4 | V16: 6.96 | W16: Approve
A17: DEAL-5015 | B17: 2024-02-23 | C17: 2024-03-27 | D17: Mei-Lin Park | E17: East | F17: SMB | G17: TD Synnex | H17: CPUs | I17: Ryzen Threadripper PRO | J17: Proposal | K17: 3153138.2 | L17: 0.051 | M17: 2992328.2 | N17: 1197656.2 | O17: 0.4002 | P17: 0.415 | Q17: 1241816.2 | R17: 33 | S17: 4.9 | T17: 8.8 | V17: 6.59 | W17: Approve
A18: DEAL-5016 | B18: 2024-03-26 | C18: 2024-04-10 | D18: Kenji Tanaka | E18: South | F18: Enterprise | G18: SHI International | H18: GPUs | I18: Radeon PRO W7900 | J18: Prospect | K18: 3044098.5 | L18: 0.0591 | M18: 2864192.3 | N18: 855205.14 | O18: 0.2986 | P18: 0.055 | Q18: 157530.58 | R18: 15 | S18: 2 | T18: 4.5 | V18: 5.63 | W18: Escalate
A19: DEAL-5017 | B19: 2024-04-08 | C19: 2024-08-21 | D19: Carlos Rivera | E19: Central | F19: Enterprise | G19: CDW | H19: Adaptive Computing | I19: Alveo U250 | J19: Proposal | K19: 1589360.2 | L19: 0.2301 | M19: 1223648.4 | N19: 577869.44 | O19: 0.4723 | P19: 0.489 | Q19: 598364.07 | R19: 135 | S19: 8.8 | T19: 8.7 | V19: 6.47 | W19: Escalate
A20: DEAL-5018 | B20: 2025-10-24 | C20: 2026-01-26 | D20: Marcus Chen | E20: East | F20: Enterprise | G20: CDW | H20: Semi-Custom | I20: Steam Deck APU | J20: Closed Won | K20: 3271539.5 | L20: 0.0891 | M20: 2980045.3 | N20: 940349.13 | O20: 0.3155 | P20: 0.968 | Q20: 2884683.9 | R20: 94 | S20: 7.4 | T20: 4.1 | V20: 6.93 | W20: Approve
A21: DEAL-5019 | B21: 2025-05-26 | C21: 2025-07-29 | D21: Carlos Rivera | E21: Central | F21: Enterprise | G21: PC Mall Gov | H21: Adaptive Computing | I21: Alveo V80 | J21: Closed Lost | K21: 2315858.6 | L21: 0.2827 | M21: 1661165.4 | N21: 731741.5 | O21: 0.4405 | P21: 0 | Q21: 0 | R21: 64 | S21: 4.7 | T21: 4.6 | U21: No decision | V21: 5.56 | W21: Escalate
A22: DEAL-5020 | B22: 2024-03-08 | C22: 2024-04-21 | D22: Mei-Lin Park | E22: East | F22: SMB | G22: Trace3 | H22: GPUs | I22: Instinct MI300X | J22: Proposal | K22: 3154631.2 | L22: 0.2197 | M22: 2461558.7 | N22: 982646.19 | O22: 0.3992 | P22: 0.481 | Q22: 1184009.7 | R22: 44 | S22: 1.8 | T22: 7 | V22: 4.69 | W22: Reject
A23: DEAL-5021 | B23: 2025-04-14 | C23: 2025-08-13 | D23: Tyler Brooks | E23: Central | F23: SMB | G23: Insight Direct | H23: GPUs | I23: Instinct MI250 | J23: Prospect | K23: 161112.54 | L23: 0.1174 | M23: 142197.93 | N23: 64054.62 | O23: 0.4505 | P23: 0.141 | Q23: 20049.91 | R23: 121 | S23: 3.3 | T23: 3.8 | V23: 6.78 | W23: Approve
A24: DEAL-5022 | B24: 2024-03-03 | C24: 2024-06-06 | D24: Mei-Lin Park | E24: East | F24: SMB | G24: SHI International | H24: Embedded | I24: Kria K26 SOM | J24: Proposal | K24: 4592187.5 | L24: 0.2184 | M24: 3589253.8 | N24: 1066338.4 | O24: 0.2971 | P24: 0.497 | Q24: 1783859.1 | R24: 95 | S24: 3.6 | T24: 9 | V24: 4.03 | W24: Reject
A25: DEAL-5023 | B25: 2024-12-26 | C25: 2025-02-27 | D25: Carlos Rivera | E25: Central | F25: Enterprise | G25: Avnet | H25: Embedded | I25: Versal AI Core | J25: Closed Lost | K25: 123625.4 | L25: 0.1771 | M25: 101731.34 | N25: 34565.88 | O25: 0.3398 | P25: 0.022 | Q25: 2238.09 | R25: 63 | S25: 9.8 | T25: 9.6 | U25: Technical fit | V25: 6.2 | W25: Escalate
A26: DEAL-5024 | B26: 2024-07-10 | C26: 2024-08-08 | D26: Natalie Frost | E26: South | F26: SMB | G26: Insight Direct | H26: Semi-Custom | I26: PlayStation Custom APU | J26: Negotiation | K26: 4506295.8 | L26: 0.1734 | M26: 3724904.1 | N26: 1552221.6 | O26: 0.4167 | P26: 0.676 | Q26: 2518035.2 | R26: 29 | S26: 1.6 | T26: 4.1 | V26: 5.59 | W26: Escalate
A27: DEAL-5025 | B27: 2024-08-24 | C27: 2024-09-12 | D27: Aisha Johnson | E27: Central | F27: Commercial | G27: Ingram Micro | H27: CPUs | I27: EPYC Bergamo 9754 | J27: Prospect | K27: 4318044.6 | L27: 0.1498 | M27: 3671201.5 | N27: 1070945.8 | O27: 0.2917 | P27: 0.141 | Q27: 517639.41 | R27: 19 | S27: 3.2 | T27: 9.7 | V27: 4.37 | W27: Reject
A28: DEAL-5026 | B28: 2024-05-28 | C28: 2024-11-09 | D28: Marcus Chen | E28: East | F28: Enterprise | G28: Connection | H28: Adaptive Computing | I28: Alveo U250 | J28: Closed Won | K28: 1509816 | L28: 0.2436 | M28: 1142024.8 | N28: 496263.81 | O28: 0.4345 | P28: 1 | Q28: 1142024.8 | R28: 165 | S28: 4.1 | T28: 5.1 | V28: 5.63 | W28: Escalate
A29: DEAL-5027 | B29: 2025-04-28 | C29: 2025-09-05 | D29: Kenji Tanaka | E29: South | F29: Enterprise | G29: World Wide Technology | H29: Semi-Custom | I29: Steam Deck APU | J29: Closed Won | K29: 4396866.7 | L29: 0.0634 | M29: 4118105.3 | N29: 1155444.3 | O29: 0.2806 | P29: 0.963 | Q29: 3965735.4 | R29: 130 | S29: 6.7 | T29: 7.9 | V29: 6.13 | W29: Escalate
A30: DEAL-5028 | B30: 2025-11-08 | C30: 2026-02-05 | D30: Natalie Frost | E30: South | F30: SMB | G30: Connection | H30: Embedded | I30: Kria K26 SOM | J30: Qualified | K30: 4345868.3 | L30: 0.2347 | M30: 3325893 | N30: 1257231.1 | O30: 0.378 | P30: 0.21 | Q30: 698437.54 | R30: 89 | S30: 8.2 | T30: 4.7 | V30: 6.33 | W30: Escalate
A31: DEAL-5029 | B31: 2025-09-20 | C31: 2026-02-11 | D31: Carlos Rivera | E31: Central | F31: Enterprise | G31: Arrow Electronics | H31: GPUs | I31: Instinct MI300X | J31: Negotiation | K31: 2239348.1 | L31: 0.1229 | M31: 1964132.2 | N31: 556127.47 | O31: 0.2831 | P31: 0.667 | Q31: 1310076.2 | R31: 144 | S31: 6.1 | T31: 1.6 | V31: 6.46 | W31: Escalate
A32: DEAL-5030 | B32: 2025-09-10 | C32: 2026-01-22 | D32: Carlos Rivera | E32: Central | F32: Enterprise | G32: Avnet | H32: Embedded | I32: Versal AI Core | J32: Qualified | K32: 676904.71 | L32: 0.1389 | M32: 582882.65 | N32: 239138.85 | O32: 0.4103 | P32: 0.297 | Q32: 173116.15 | R32: 134 | S32: 1.5 | T32: 9.3 | V32: 5.01 | W32: Escalate
A33: DEAL-5031 | B33: 2025-08-04 | C33: 2025-09-09 | D33: Marcus Chen | E33: East | F33: Enterprise | G33: Presidio | H33: Embedded | I33: Kria K26 SOM | J33: Prospect | K33: 1744817.4 | L33: 0.1409 | M33: 1498972.6 | N33: 550496.58 | O33: 0.3672 | P33: 0.086 | Q33: 128911.64 | R33: 36 | S33: 8.6 | T33: 5.8 | V33: 6.97 | W33: Approve
A34: DEAL-5032 | B34: 2024-05-30 | C34: 2024-08-09 | D34: Tyler Brooks | E34: Central | F34: SMB | G34: World Wide Technology | H34: CPUs | I34: Ryzen 9 7950X | J34: Closed Lost | K34: 4466577.4 | L34: 0.1376 | M34: 3851976.4 | N34: 1758830.6 | O34: 0.4566 | P34: 0 | Q34: 0 | R34: 71 | S34: 9.3 | T34: 3.5 | V34: 8.15 | W34: Approve
A35: DEAL-5033 | B35: 2025-08-28 | C35: 2025-12-04 | D35: Rachel Okafor | E35: South | F35: Commercial | G35: Arrow Electronics | H35: GPUs | I35: Radeon PRO W7900 | J35: Proposal | K35: 3278948.1 | L35: 0.0678 | M35: 3056635.4 | N35: 1018624.8 | O35: 0.3333 | P35: 0.461 | Q35: 1409108.9 | R35: 98 | S35: 3.6 | T35: 3.9 | V35: 6.33 | W35: Escalate
A36: DEAL-5034 | B36: 2024-08-02 | C36: 2024-09-16 | D36: Rachel Okafor | E36: South | F36: Commercial | G36: World Wide Technology | H36: Adaptive Computing | I36: Alveo V80 | J36: Closed Lost | K36: 4291569.6 | L36: 0.2048 | M36: 3412656.1 | N36: 1131345.5 | O36: 0.3315 | P36: 0 | Q36: 0 | R36: 45 | S36: 2.5 | T36: 6.7 | U36: Price | V36: 4.51 | W36: Reject
A37: DEAL-5035 | B37: 2024-09-25 | C37: 2025-02-12 | D37: Marcus Chen | E37: East | F37: Enterprise | G37: World Wide Technology | H37: Semi-Custom | I37: PlayStation Custom APU | J37: Qualified | K37: 4862013.7 | L37: 0.1777 | M37: 3998033.8 | N37: 1663713 | O37: 0.4161 | P37: 0.297 | Q37: 1187416 | R37: 140 | S37: 5.5 | T37: 3 | V37: 6.67 | W37: Approve
A38: DEAL-5036 | B38: 2025-10-22 | C38: 2025-11-10 | D38: Rachel Okafor | E38: South | F38: Commercial | G38: Connection | H38: Semi-Custom | I38: Xbox Custom APU | J38: Prospect | K38: 4285882.7 | L38: 0.161 | M38: 3595855.6 | N38: 1278890.5 | O38: 0.3557 | P38: 0.114 | Q38: 409927.54 | R38: 19 | S38: 9.4 | T38: 4.5 | V38: 7.09 | W38: Approve
A39: DEAL-5037 | B39: 2024-07-26 | C39: 2024-09-11 | D39: Sofia Delgado | E39: East | F39: Public Sector | G39: SHI International | H39: CPUs | I39: Ryzen Threadripper PRO | J39: Qualified | K39: 1314084.8 | L39: 0.2142 | M39: 1032607.9 | N39: 338079.15 | O39: 0.3274 | P39: 0.243 | Q39: 250923.71 | R39: 47 | S39: 5.1 | T39: 1 | V39: 5.9 | W39: Escalate
A40: DEAL-5038 | B40: 2025-10-18 | C40: 2026-01-01 | D40: Rachel Okafor | E40: South | F40: Commercial | G40: Arrow Electronics | H40: Adaptive Computing | I40: Alveo V80 | J40: Qualified | K40: 2480888.8 | L40: 0.1703 | M40: 2058393.4 | N40: 732165.65 | O40: 0.3557 | P40: 0.244 | Q40: 502247.99 | R40: 75 | S40: 9.3 | T40: 5.5 | V40: 6.84 | W40: Approve
...

Sheet Data_Reps
A1: rep_name | B1: region | C1: segment | D1: annual_quota | E1: actual_revenue | F1: quota_attainment_pct | G1: deals_won | H1: deals_lost | I1: win_rate | J1: avg_deal_size | K1: avg_sales_cycle_days | L1: avg_discount_rate | M1: avg_gross_margin_pct | N1: year
A2: Jordan Mitchell | B2: West | C2: Enterprise | D2: 7348119.8 | E2: 4275870.9 | F2: 0.5819 | G2: 12 | H2: 3 | I2: 0.8 | J2: 350950.28 | K2: 115 | L2: 0.2414 | M2: 0.3281 | N2: 2024
A3: Priya Nair | B3: West | C3: Commercial | D3: 7159328.7 | E3: 5361621.2 | F3: 0.7489 | G3: 31 | H3: 19 | I3: 0.62 | J3: 168452.33 | K3: 55 | L3: 0.1728 | M3: 0.342 | N3: 2024
A4: Marcus Chen | B4: East | C4: Enterprise | D4: 9568062.4 | E4: 6915795.5 | F4: 0.7228 | G4: 34 | H4: 22 | I4: 0.6071 | J4: 201799.31 | K4: 48 | L4: 0.2272 | M4: 0.3175 | N4: 2024
A5: Sofia Delgado | B5: East | C5: Public Sector | D5: 6830647.9 | E5: 8043087.9 | F5: 1.1775 | G5: 33 | H5: 15 | I5: 0.6875 | J5: 238121.24 | K5: 86 | L5: 0.1201 | M5: 0.3993 | N5: 2024
A6: Tyler Brooks | B6: Central | C6: SMB | D6: 9661128 | E6: 12233886 | F6: 1.2663 | G6: 60 | H6: 18 | I6: 0.7692 | J6: 200581.67 | K6: 37 | L6: 0.1242 | M6: 0.4398 | N6: 2024
A7: Aisha Johnson | B7: Central | C7: Commercial | D7: 5309498.7 | E7: 4970752.7 | F7: 0.9362 | G7: 8 | H7: 2 | I7: 0.8 | J7: 562269.66 | K7: 59 | L7: 0.1701 | M7: 0.4088 | N7: 2024
A8: Kenji Tanaka | B8: South | C8: Enterprise | D8: 11800683 | E8: 13472840 | F8: 1.1417 | G8: 24 | H8: 8 | I8: 0.75 | J8: 547572.84 | K8: 97 | L8: 0.1336 | M8: 0.2831 | N8: 2024
A9: Rachel Okafor | B9: South | C9: Commercial | D9: 4908835.1 | E9: 4643758 | F9: 0.946 | G9: 8 | H9: 2 | I9: 0.8 | J9: 519285.9 | K9: 116 | L9: 0.2383 | M9: 0.3053 | N9: 2024
A10: Derek Walsh | B10: West | C10: Public Sector | D10: 5433641.7 | E10: 3935586.7 | F10: 0.7243 | G10: 14 | H10: 4 | I10: 0.7778 | J10: 269055.34 | K10: 102 | L10: 0.1717 | M10: 0.4135 | N10: 2024
A11: Mei-Lin Park | B11: East | C11: SMB | D11: 8287111.3 | E11: 9879894 | F11: 1.1922 | G11: 19 | H11: 5 | I11: 0.7917 | J11: 506372.47 | K11: 112 | L11: 0.1786 | M11: 0.3318 | N11: 2024
A12: Carlos Rivera | B12: Central | C12: Enterprise | D12: 3177603 | E12: 3600859.7 | F12: 1.1332 | G12: 6 | H12: 4 | I12: 0.6 | J12: 560002.21 | K12: 92 | L12: 0.1296 | M12: 0.3553 | N12: 2024
A13: Natalie Frost | B13: South | C13: SMB | D13: 6361838.3 | E13: 6152533.8 | F13: 0.9671 | G13: 25 | H13: 12 | I13: 0.6757 | J13: 237652.11 | K13: 72 | L13: 0.1115 | M13: 0.3429 | N13: 2024

Sheet Data_Monthly
A1: rep_name | B1: region | C1: month | D1: actual_revenue | E1: plan_revenue | F1: variance_vs_plan | G1: variance_pct | H1: actual_discount_rate | I1: actual_gm_pct
A2: Jordan Mitchell | B2: West | C2: 2024-01 | D2: 349193.53 | E2: 322370.96 | F2: 26822.57 | G2: 0.0832 | H2: 0.1473 | I2: 0.2698
A3: Jordan Mitchell | B3: West | C3: 2024-02 | D3: 394911.92 | E3: 388225.74 | F3: 6686.18 | G3: 0.0172 | H3: 0.14 | I3: 0.4106
A4: Jordan Mitchell | B4: West | C4: 2024-03 | D4: 274968.49 | E4: 387026.09 | F4: -112057.6 | G4: -0.2895 | H4: 0.2171 | I4: 0.3751
A5: Jordan Mitchell | B5: West | C5: 2024-04 | D5: 289088.6 | E5: 357832.79 | F5: -68744.19 | G5: -0.1921 | H5: 0.2152 | I5: 0.3712
A6: Jordan Mitchell | B6: West | C6: 2024-05 | D6: 335144.66 | E6: 328130.39 | F6: 7014.27 | G6: 0.0214 | H6: 0.1433 | I6: 0.3556
A7: Jordan Mitchell | B7: West | C7: 2024-06 | D7: 272143.73 | E7: 355467.26 | F7: -83323.53 | G7: -0.2344 | H7: 0.2048 | I7: 0.3377
A8: Jordan Mitchell | B8: West | C8: 2024-07 | D8: 318672.66 | E8: 388523.75 | F8: -69851.09 | G8: -0.1798 | H8: 0.0813 | I8: 0.2658
A9: Jordan Mitchell | B9: West | C9: 2024-08 | D9: 330439.16 | E9: 385263.68 | F9: -54824.52 | G9: -0.1423 | H9: 0.1163 | I9: 0.2734
A10: Jordan Mitchell | B10: West | C10: 2024-09 | D10: 442581.31 | E10: 365982.32 | F10: 76598.99 | G10: 0.2093 | H10: 0.2284 | I10: 0.2872
A11: Jordan Mitchell | B11: West | C11: 2024-10 | D11: 437822.66 | E11: 451572.44 | F11: -13749.78 | G11: -0.0304 | H11: 0.229 | I11: 0.2638
A12: Jordan Mitchell | B12: West | C12: 2024-11 | D12: 369770.16 | E12: 474798.72 | F12: -105028.56 | G12: -0.2212 | H12: 0.2474 | I12: 0.3335
A13: Jordan Mitchell | B13: West | C13: 2024-12 | D13: 349847.3 | E13: 441509.5 | F13: -91662.2 | G13: -0.2076 | H13: 0.1367 | I13: 0.2804
... A145: Natalie Frost | B145: South | C145: 2024-12 | D145: 602175.58 | E145: 659928.29 | F145: -57752.71 | G145: -0.0875 | H145: 0.1371 | I145: 0.2931

Sheet Assumptions
A1: ⚙ Model Assumptions & Inputs — Middleton Finance Suite
A3: DISCOUNT POLICY
A4: Max Allowable Discount — Enterprise | B4: 0.3 | C4: Policy cap per deal approval matrix
A5: Max Allowable Discount — Commercial | B5: 0.22 | C5: Policy cap per deal approval matrix
A6: Max Allowable Discount — SMB/Public | B6: 0.18 | C6: Policy cap per deal approval matrix
A7: Plan Discount Rate (blended FY2024) | B7: 0.14 | C7: Finance budget assumption
A9: GROSS MARGIN TARGETS
A10: Target GM% — GPUs | B10: 0.35 | C10: FY2024 product finance target
A11: Target GM% — CPUs | B11: 0.38 | C11: FY2024 product finance target
A12: Target GM% — Embedded | B12: 0.42 | C12: FY2024 product finance target
A13: Target GM% — Semi-Custom | B13: 0.28 | C13: FY2024 product finance target
A14: Target GM% — Adaptive Computing | B14: 0.4 | C14: FY2024 product finance target
A16: REBATE ACCRUAL
A17: Rebate Rate — Gold Partners | B17: 0.05 | C17: Applied to net revenue, accrued monthly
A18: Rebate Rate — Silver Partners | B18: 0.03 | C18: Applied to net revenue, accrued monthly
A19: Rebate Rate — Bronze Partners | B19: 0.015 | C19: Applied to net revenue, accrued monthly
A20: MDF Allocation % of Net Revenue | B20: 0.02 | C20: Market Development Funds annual budget
A22: DEAL SCORING WEIGHTS
A23: Weight — Gross Margin Component | B23: 0.35 | C23: Composite score formula — must sum to 100%
A24: Weight — Discount Component | B24: 0.25 | C24: Composite score formula
A25: Weight — Strategic Value Component | B25: 0.25 | C25: Composite score formula
A26: Weight — Risk Component | B26: 0.15 | C26: Composite score formula
A27: Auto-Approve Threshold (score ≥) | B27: 6.5 | C27: Deals above this score auto-cleared
A28: Escalate Threshold (score <) | B28: 5 | C28: Deals below this require VP sign-off
A31: COLOR CODING STANDARD
A32: Blue text | C32: Hardcoded input — editable for scenario analysis
A33: Black text | C33: Formula — calculated, do not edit directly
A34: Green text | C34: Cross-sheet reference link

Sheet Pricing & Rebates
A1: 💰 Pricing & Rebate Intelligence — FY2024 Actuals vs. Plan
A3: A | Discount & Margin by Product Category [sourced from Data_Transactions]
A4: Product Category | B4: Orders | C4: Net Revenue ($M) | D4: Actual Disc% | E4: Plan Disc% | F4: Variance (pp) | G4: Actual GM% | H4: Target GM% | I4: GM vs Target | J4: Rebate Accrual ($K) | K4: Status
A5: GPUs | B5: 304 | C5: =SUMIF(Data_Transactions!H:H,A5,Data_Transactions!O:O)/1000000 -> 517.45006 | D5: =AVERAGEIF(Data_Transactions!H:H,A5,Data_Transactions!M:M) -> 0.094734866 | E5: =AVERAGEIF(Data_Transactions!H:H,A5,Data_Transactions!S:S) -> 0.089678182 | F5: =D5-E5 -> 0.0050566845 | G5: =AVERAGEIF(Data_Transactions!H:H,A5,Data_Transactions!R:R) -> 0.31320171 | H5: =Assumptions!B9 -> 0 | I5: =G5-H5 -> 0.31320171 | J5: =C5*Assumptions!B15*1000 -> 0 | K5: =IF(ABS(F5)<0.005,"✓ On Plan",IF(F5>0,"⚠ Over-Disc.","↓ Under Plan")) -> ⚠ Over-Disc.
A6: CPUs | B6: 309 | C6: =SUMIF(Data_Transactions!H:H,A6,Data_Transactions!O:O)/1000000 -> 167.19159 | D6: =AVERAGEIF(Data_Transactions!H:H,A6,Data_Transactions!M:M) -> 0.096171113 | E6: =AVERAGEIF(Data_Transactions!H:H,A6,Data_Transactions!S:S) -> 0.091160714 | F6: =D6-E6 -> 0.0050103992 | G6: =AVERAGEIF(Data_Transactions!H:H,A6,Data_Transactions!R:R) -> 0.35644412 | H6: =Assumptions!B10 -> 0.35 | I6: =G6-H6 -> 0.0064441176 | J6: =C6*Assumptions!B15*1000 -> 0 | K6: =IF(ABS(F6)<0.005,"✓ On Plan",IF(F6>0,"⚠ Over-Disc.","↓ Under Plan")) -> ⚠ Over-Disc.
A7: Embedded | B7: 311 | C7: =SUMIF(Data_Transactions!H:H,A7,Data_Transactions!O:O)/1000000 -> 49.525815 | D7: =AVERAGEIF(Data_Transactions!H:H,A7,Data_Transactions!M:M) -> 0.095179506 | E7: =AVERAGEIF(Data_Transactions!H:H,A7,Data_Transactions!S:S) -> 0.090642918 | F7: =D7-E7 -> 0.004536588 | G7: =AVERAGEIF(Data_Transactions!H:H,A7,Data_Transactions!R:R) -> 0.39046073 | H7: =Assumptions!B11 -> 0.38 | I7: =G7-H7 -> 0.01046073 | J7: =C7*Assumptions!B15*1000 -> 0 | K7: =IF(ABS(F7)<0.005,"✓ On Plan",IF(F7>0,"⚠ Over-Disc.","↓ Under Plan")) -> ✓ On Plan
A8: Semi-Custom | B8: 354 | C8: =SUMIF(Data_Transactions!H:H,A8,Data_Transactions!O:O)/1000000 -> 86.427983 | D8: =AVERAGEIF(Data_Transactions!H:H,A8,Data_Transactions!M:M) -> 0.095889366 | E8: =AVERAGEIF(Data_Transactions!H:H,A8,Data_Transactions!S:S) -> 0.091378341 | F8: =D8-E8 -> 0.0045110244 | G8: =AVERAGEIF(Data_Transactions!H:H,A8,Data_Transactions!R:R) -> 0.24582537 | H8: =Assumptions!B12 -> 0.42 | I8: =G8-H8 -> -0.17417463 | J8: =C8*Assumptions!B15*1000 -> 0 | K8: =IF(ABS(F8)<0.005,"✓ On Plan",IF(F8>0,"⚠ Over-Disc.","↓ Under Plan")) -> ✓ On Plan
A9: Adaptive Computing | B9: 348 | C9: =SUMIF(Data_Transactions!H:H,A9,Data_Transactions!O:O)/1000000 -> 217.18113 | D9: =AVERAGEIF(Data_Transactions!H:H,A9,Data_Transactions!M:M) -> 0.097551883 | E9: =AVERAGEIF(Data_Transactions!H:H,A9,Data_Transactions!S:S) -> 0.092691213 | F9: =D9-E9 -> 0.0048606695 | G9: =AVERAGEIF(Data_Transactions!H:H,A9,Data_Transactions!R:R) -> 0.33324571 | H9: =Assumptions!B13 -> 0.28 | I9: =G9-H9 -> 0.053245711 | J9: =C9*Assumptions!B15*1000 -> 0 | K9: =IF(ABS(F9)<0.005,"✓ On Plan",IF(F9>0,"⚠ Over-Disc.","↓ Under Plan")) -> ✓ On Plan
A10: TOTAL / BLENDED AVERAGE | B10: =SUM(B5:B9) -> 1626 | C10: =SUM(C5:C9) -> 1037.7766 | D10: =AVERAGE(D5:D9) -> 0.095905347 | E10: =AVERAGE(E5:E9) -> 0.091110274 | F10: =D10-E10 -> 0.0047950731 | G10: =AVERAGE(G5:G9) -> 0.32783553 | H10: =AVERAGE(H5:H9) -> 0.286 | I10: =G10-H10 -> 0.041835527 | J10: =SUM(J5:J9) -> 0
A12: B | Channel Partner Rebate Accrual Schedule [Data_Transactions + rebate_tiers.csv]
A13: Channel Partner | B13: Tier | C13: Rev Threshold ($M) | D13: Net Revenue ($M) | E13: Rebate Rate | F13: Accrued Rebate ($K) | G13: MDF Eligible | H13: Contract End
A14: Arrow Electronics | B14: Gold | C14: 5 | D14: =SUMIF(Data_Transactions!G:G,A14,Data_Transactions!O:O)/1000000 -> 82.992383 | E14: =Assumptions!B15 -> 0 | F14: =D14*E14*1000 -> 0 | G14: Yes | H14: 2024-12-31
A15: Avnet | B15: Silver | C15: 1 | D15: =SUMIF(Data_Transactions!G:G,A15,Data_Transactions!O:O)/1000000 -> 102.25896 | E15: =Assumptions!B16 -> 0 | F15: =D15*E15*1000 -> 0 | G15: Yes | H15: 2024-12-31
A16: CDW | B16: Silver | C16: 2.5 | D16: =SUMIF(Data_Transactions!G:G,A16,Data_Transactions!O:O)/1000000 -> 85.607143 | E16: =Assumptions!B16 -> 0 | F16: =D16*E16*1000 -> 0 | G16: Yes | H16: 2024-12-31
A17: Connection | B17: Silver | C17: 2.5 | D17: =SUMIF(Data_Transactions!G:G,A17,Data_Transactions!O:O)/1000000 -> 73.968889 | E17: =Assumptions!B16 -> 0 | F17: =D17*E17*1000 -> 0 | G17: Yes | H17: 2024-12-31
A18: Ingram Micro | B18: Bronze | C18: 0.5 | D18: =SUMIF(Data_Transactions!G:G,A18,Data_Transactions!O:O)/1000000 -> 81.14169 | E18: =Assumptions!B17 -> 0.05 | F18: =D18*E18*1000 -> 4057.0845 | G18: No | H18: 2024-12-31
A19: Insight Direct | B19: Gold | C19: 10 | D19: =SUMIF(Data_Transactions!G:G,A19,Data_Transactions!O:O)/1000000 -> 81.396501 | E19: =Assumptions!B15 -> 0 | F19: =D19*E19*1000 -> 0 | G19: Yes | H19: 2024-12-31
A20: PC Mall Gov | B20: Gold | C20: 10 | D20: =SUMIF(Data_Transactions!G:G,A20,Data_Transactions!O:O)/1000000 -> 87.086036 | E20: =Assumptions!B15 -> 0 | F20: =D20*E20*1000 -> 0 | G20: Yes | H20: 2024-12-31
A21: Presidio | B21: Bronze | C21: 0.5 | D21: =SUMIF(Data_Transactions!G:G,A21,Data_Transactions!O:O)/1000000 -> 82.775394 | E21: =Assumptions!B17 -> 0.05 | F21: =D21*E21*1000 -> 4138.7697 | G21: Yes | H21: 2024-12-31
A22: SHI International | B22: Gold | C22: 10 | D22: =SUMIF(Data_Transactions!G:G,A22,Data_Transactions!O:O)/1000000 -> 91.326 | E22: =Assumptions!B15 -> 0 | F22: =D22*E22*1000 -> 0 | G22: Yes | H22: 2024-12-31
A23: TD Synnex | B23: Bronze | C23: 0.5 | D23: =SUMIF(Data_Transactions!G:G,A23,Data_Transactions!O:O)/1000000 -> 90.603035 | E23: =Assumptions!B17 -> 0.05 | F23: =D23*E23*1000 -> 4530.1517 | G23: Yes | H23: 2024-12-31
A24: Trace3 | B24: Bronze | C24: 0.5 | D24: =SUMIF(Data_Transactions!G:G,A24,Data_Transactions!O:O)/1000000 -> 81.712846 | E24: =Assumptions!B17 -> 0.05 | F24: =D24*E24*1000 -> 4085.6423 | G24: Yes | H24: 2024-12-31
A25: World Wide Technology | B25: Gold | C25: 5 | D25: =SUMIF(Data_Transactions!G:G,A25,Data_Transactions!O:O)/1000000 -> 96.907706 | E25: =Assumptions!B15 -> 0 | F25: =D25*E25*1000 -> 0 | G25: No | H25: 2024-12-31
A27: C | Quarterly Discount Variance vs. Plan — FY2024 [SUMIF/AVERAGEIF from Data_Transactions]
A28: Quarter | B28: Orders | C28: Net Revenue ($M) | D28: Actual Disc% | E28: Plan Disc% | F28: Variance (pp) | G28: Avg GM% | H28: Trend
A29: Q1 2024 | B29: =COUNTIF(Data_Transactions!C:C,A29) -> 407 | C29: =SUMIF(Data_Transactions!C:C,A29,Data_Transactions!O:O)/1000000 -> 84.276776 | D29: =AVERAGEIF(Data_Transactions!C:C,A29,Data_Transactions!M:M) -> 0.095661179 | E29: =AVERAGEIF(Data_Transactions!C:C,A29,Data_Transactions!S:S) -> 0.090677887 | F29: =D29-E29 -> 0.0049832924 | G29: =AVERAGEIF(Data_Transactions!C:C,A29,Data_Transactions!R:R) -> 0.32579853 | H29: =IF(F29<-0.005,"▲ Improving",IF(F29>0.005,"▼ Worsening","→ Stable")) -> → Stable
A30: Q2 2024 | B30: =COUNTIF(Data_Transactions!C:C,A30) -> 400 | C30: =SUMIF(Data_Transactions!C:C,A30,Data_Transactions!O:O)/1000000 -> 93.042374 | D30: =AVERAGEIF(Data_Transactions!C:C,A30,Data_Transactions!M:M) -> 0.09480675 | E30: =AVERAGEIF(Data_Transactions!C:C,A30,Data_Transactions!S:S) -> 0.09046125 | F30: =D30-E30 -> 0.0043455 | G30: =AVERAGEIF(Data_Transactions!C:C,A30,Data_Transactions!R:R) -> 0.3281745 | H30: =IF(F30<-0.005,"▲ Improving",IF(F30>0.005,"▼ Worsening","→ Stable")) -> → Stable
A31: Q3 2024 | B31: =COUNTIF(Data_Transactions!C:C,A31) -> 422 | C31: =SUMIF(Data_Transactions!C:C,A31,Data_Transactions!O:O)/1000000 -> 93.443293 | D31: =AVERAGEIF(Data_Transactions!C:C,A31,Data_Transactions!M:M) -> 0.09114455 | E31: =AVERAGEIF(Data_Transactions!C:C,A31,Data_Transactions!S:S) -> 0.086217536 | F31: =D31-E31 -> 0.0049270142 | G31: =AVERAGEIF(Data_Transactions!C:C,A31,Data_Transactions!R:R) -> 0.32653246 | H31: =IF(F31<-0.005,"▲ Improving",IF(F31>0.005,"▼ Worsening","→ Stable")) -> → Stable
A32: Q4 2024 | B32: =COUNTIF(Data_Transactions!C:C,A32) -> 397 | C32: =SUMIF(Data_Transactions!C:C,A32,Data_Transactions!O:O)/1000000 -> 81.464039 | D32: =AVERAGEIF(Data_Transactions!C:C,A32,Data_Transactions!M:M) -> 0.097090428 | E32: =AVERAGEIF(Data_Transactions!C:C,A32,Data_Transactions!S:S) -> 0.092718892 | F32: =D32-E32 -> 0.0043715365 | G32: =AVERAGEIF(Data_Transactions!C:C,A32,Data_Transactions!R:R) -> 0.32623552 | H32: =IF(F32<-0.005,"▲ Improving",IF(F32>0.005,"▼ Worsening","→ Stable")) -> → Stable

Sheet Deal Scorecard
A1: 📋 Deal Evaluation Scorecard — Pipeline Analysis & Approval Status
A3: A | Scenario Model — Discount Rate Sensitivity [inputs from Assumptions sheet]
A4: Scenario | B4: Discount Rate | C4: Net Deal Value | D4: COGS (est.) | E4: Gross Margin $ | F4: GM% | G4: vs. Base Case | H4: Auto-Approve?
A5: Conservative (Low Disc.) | B5: =Assumptions!B6*0.6 -> 0.108 | C5: =2385449*(1-B5) -> 2127820.5 | D5: =C5*0.62 -> 1319248.7 | E5: =C5-D5 -> 808571.79 | F5: =IFERROR(E5/C5,0) -> 0.38 | G5: =E5-E6 -> 29007.06 | H5: =IF(AND(F5>0.32,B5<Assumptions!B24/10),"✓ Auto-Approve","⚠ Escalate") -> ⚠ Escalate
A6: Base Case | B6: =Assumptions!B7 -> 0.14 | C6: =2385449*(1-B6) -> 2051486.1 | D6: =C6*0.62 -> 1271921.4 | E6: =C6-D6 -> 779564.73 | F6: =IFERROR(E6/C6,0) -> 0.38 | G6: — | H6: =IF(AND(F6>0.32,B6<Assumptions!B24/10),"✓ Auto-Approve","⚠ Escalate") -> ⚠ Escalate
A7: Stretched (High Disc.) | B7: =Assumptions!B5 -> 0.22 | C7: =2385449*(1-B7) -> 1860650.2 | D7: =C7*0.62 -> 1153603.1 | E7: =C7-D7 -> 707047.08 | F7: =IFERROR(E7/C7,0) -> 0.38 | G7: =E7-E6 -> -72517.65 | H7: =IF(AND(F7>0.32,B7<Assumptions!B24/10),"✓ Auto-Approve","⚠ Escalate") -> ⚠ Escalate
A8: Max Policy — Enterprise | B8: =Assumptions!B4 -> 0.3 | C8: =2385449*(1-B8) -> 1669814.3 | D8: =C8*0.62 -> 1035284.9 | E8: =C8-D8 -> 634529.43 | F8: =IFERROR(E8/C8,0) -> 0.38 | G8: =E8-E6 -> -145035.3 | H8: =IF(AND(F8>0.32,B8<Assumptions!B24/10),"✓ Auto-Approve","⚠ Escalate") -> ⚠ Escalate
A10: B | Deal Pipeline — Scored & Classified [1200 Deals from Data_Deals]
A11: Deal ID | B11: Stage | C11: Product Category | D11: Region | E11: Segment | F11: List Value | G11: Disc% | H11: Net Value | I11: GM% | J11: Score | K11: Recommendation | L11: Partner
A12: DEAL-5613 | B12: Closed Lost | C12: Semi-Custom | D12: East | E12: Enterprise | F12: 1294228.1 | G12: 0.0879 | H12: 1180465.4 | I12: 0.4285 | J12: 8.9 | K12: Approve | L12: Avnet
A13: DEAL-6028 | B13: Proposal | C13: Adaptive Computing | D13: Central | E13: Enterprise | F13: 4058196.8 | G13: 0.0737 | H13: 3759107.7 | I13: 0.4519 | J13: 8.7 | K13: Approve | L13: Arrow Electronics
A14: DEAL-6024 | B14: Negotiation | C14: Adaptive Computing | D14: West | E14: Enterprise | F14: 833245.9 | G14: 0.0543 | H14: 788000.65 | I14: 0.4703 | J14: 8.7 | K14: Approve | L14: Avnet
A15: DEAL-6171 | B15: Negotiation | C15: Semi-Custom | D15: West | E15: Public Sector | F15: 918305.14 | G15: 0.1061 | H15: 820872.96 | I15: 0.4538 | J15: 8.6 | K15: Approve | L15: Insight Direct
A16: DEAL-5295 | B16: Closed Won | C16: Adaptive Computing | D16: East | E16: SMB | F16: 450853.65 | G16: 0.0515 | H16: 427634.69 | I16: 0.4584 | J16: 8.5 | K16: Approve | L16: Connection
A17: DEAL-5955 | B17: Closed Lost | C17: Embedded | D17: South | E17: SMB | F17: 2126849.5 | G17: 0.0871 | H17: 1941600.9 | I17: 0.4257 | J17: 8.5 | K17: Approve | L17: Presidio
A18: DEAL-5082 | B18: Qualified | C18: CPUs | D18: East | E18: Enterprise | F18: 3508412.1 | G18: 0.074 | H18: 3248789.6 | I18: 0.4391 | J18: 8.5 | K18: Approve | L18: CDW
A19: DEAL-5337 | B19: Closed Won | C19: Embedded | D19: Central | E19: Enterprise | F19: 4466937.4 | G19: 0.0758 | H19: 4128343.5 | I19: 0.4579 | J19: 8.5 | K19: Approve | L19: World Wide Technology
A20: DEAL-6075 | B20: Proposal | C20: Semi-Custom | D20: South | E20: Commercial | F20: 1815291.9 | G20: 0.0879 | H20: 1655727.7 | I20: 0.4286 | J20: 8.5 | K20: Approve | L20: Trace3
A21: DEAL-5996 | B21: Proposal | C21: GPUs | D21: West | E21: Public Sector | F21: 2485503 | G21: 0.0868 | H21: 2269761.3 | I21: 0.4223 | J21: 8.4 | K21: Approve | L21: TD Synnex
A22: DEAL-5320 | B22: Qualified | C22: Embedded | D22: Central | E22: Commercial | F22: 2993371.1 | G22: 0.0927 | H22: 2715885.6 | I22: 0.432 | J22: 8.4 | K22: Approve | L22: TD Synnex
A23: DEAL-5639 | B23: Qualified | C23: Embedded | D23: South | E23: SMB | F23: 512271.68 | G23: 0.0557 | H23: 483738.15 | I23: 0.3317 | J23: 8.3 | K23: Approve | L23: TD Synnex
... A91: DEAL-6006 | B91: Closed Lost | C91: CPUs | D91: Central | E91: Commercial | F91: 4697321.8 | G91: 0.0838 | H91: 4303686.2 | I91: 0.4303 | J91: 7.6 | K91: Approve | L91: Connection

Sheet Channel Performance
A1: 📊 Channel Sales Performance — FY2024 Rep Scorecard & Month-End Close
A3: A | Rep Performance vs. Quota — FY2024 [XLOOKUP from Data_Reps]
A4: Rep Name | B4: Region | C4: Segment | D4: Annual Quota | E4: Actual Revenue | F4: Attainment % | G4: Avg Deal Size | H4: Win Rate | I4: Avg Disc% | J4: Avg GM%
A5: Tyler Brooks | B5: Central | C5: SMB | D5: =IFERROR(xlookup(A5,Data_Reps!A:A,Data_Reps!D:D),0) -> 0 | E5: =IFERROR(xlookup(A5,Data_Reps!A:A,Data_Reps!E:E),0) -> 0 | F5: =IFERROR(E5/D5,0) -> 0 | G5: =IFERROR(xlookup(A5,Data_Reps!A:A,Data_Reps!J:J),0) -> 0 | H5: =IFERROR(xlookup(A5,Data_Reps!A:A,Data_Reps!I:I),0) -> 0 | I5: =IFERROR(xlookup(A5,Data_Reps!A:A,Data_Reps!L:L),0) -> 0 | J5: =IFERROR(xlookup(A5,Data_Reps!A:A,Data_Reps!M:M),0) -> 0
A6: Mei-Lin Park | B6: East | C6: SMB | D6: =IFERROR(xlookup(A6,Data_Reps!A:A,Data_Reps!D:D),0) -> 0 | E6: =IFERROR(xlookup(A6,Data_Reps!A:A,Data_Reps!E:E),0) -> 0 | F6: =IFERROR(E6/D6,0) -> 0 | G6: =IFERROR(xlookup(A6,Data_Reps!A:A,Data_Reps!J:J),0) -> 0 | H6: =IFERROR(xlookup(A6,Data_Reps!A:A,Data_Reps!I:I),0) -> 0 | I6: =IFERROR(xlookup(A6,Data_Reps!A:A,Data_Reps!L:L),0) -> 0 | J6: =IFERROR(xlookup(A6,Data_Reps!A:A,Data_Reps!M:M),0) -> 0
A7: Sofia Delgado | B7: East | C7: Public Sector | D7: =IFERROR(xlookup(A7,Data_Reps!A:A,Data_Reps!D:D),0) -> 0 | E7: =IFERROR(xlookup(A7,Data_Reps!A:A,Data_Reps!E:E),0) -> 0 | F7: =IFERROR(E7/D7,0) -> 0 | G7: =IFERROR(xlookup(A7,Data_Reps!A:A,Data_Reps!J:J),0) -> 0 | H7: =IFERROR(xlookup(A7,Data_Reps!A:A,Data_Reps!I:I),0) -> 0 | I7: =IFERROR(xlookup(A7,Data_Reps!A:A,Data_Reps!L:L),0) -> 0 | J7: =IFERROR(xlookup(A7,Data_Reps!A:A,Data_Reps!M:M),0) -> 0
A8: Kenji Tanaka | B8: South | C8: Enterprise | D8: =IFERROR(xlookup(A8,Data_Reps!A:A,Data_Reps!D:D),0) -> 0 | E8: =IFERROR(xlookup(A8,Data_Reps!A:A,Data_Reps!E:E),0) -> 0 | F8: =IFERROR(E8/D8,0) -> 0 | G8: =IFERROR(xlookup(A8,Data_Reps!A:A,Data_Reps!J:J),0) -> 0 | H8: =IFERROR(xlookup(A8,Data_Reps!A:A,Data_Reps!I:I),0) -> 0 | I8: =IFERROR(xlookup(A8,Data_Reps!A:A,Data_Reps!L:L),0) -> 0 | J8: =IFERROR(xlookup(A8,Data_Reps!A:A,Data_Reps!M:M),0) -> 0
A9: Carlos Rivera | B9: Central | C9: Enterprise | D9: =IFERROR(xlookup(A9,Data_Reps!A:A,Data_Reps!D:D),0) -> 0 | E9: =IFERROR(xlookup(A9,Data_Reps!A:A,Data_Reps!E:E),0) -> 0 | F9: =IFERROR(E9/D9,0) -> 0 | G9: =IFERROR(xlookup(A9,Data_Reps!A:A,Data_Reps!J:J),0) -> 0 | H9: =IFERROR(xlookup(A9,Data_Reps!A:A,Data_Reps!I:I),0) -> 0 | I9: =IFERROR(xlookup(A9,Data_Reps!A:A,Data_Reps!L:L),0) -> 0 | J9: =IFERROR(xlookup(A9,Data_Reps!A:A,Data_Reps!M:M),0) -> 0
A10: Natalie Frost | B10: South | C10: SMB | D10: =IFERROR(xlookup(A10,Data_Reps!A:A,Data_Reps!D:D),0) -> 0 | E10: =IFERROR(xlookup(A10,Data_Reps!A:A,Data_Reps!E:E),0) -> 0 | F10: =IFERROR(E10/D10,0) -> 0 | G10: =IFERROR(xlookup(A10,Data_Reps!A:A,Data_Reps!J:J),0) -> 0 | H10: =IFERROR(xlookup(A10,Data_Reps!A:A,Data_Reps!I:I),0) -> 0 | I10: =IFERROR(xlookup(A10,Data_Reps!A:A,Data_Reps!L:L),0) -> 0 | J10: =IFERROR(xlookup(A10,Data_Reps!A:A,Data_Reps!M:M),0) -> 0
A11: Rachel Okafor | B11: South | C11: Commercial | D11: =IFERROR(xlookup(A11,Data_Reps!A:A,Data_Reps!D:D),0) -> 0 | E11: =IFERROR(xlookup(A11,Data_Reps!A:A,Data_Reps!E:E),0) -> 0 | F11: =IFERROR(E11/D11,0) -> 0 | G11: =IFERROR(xlookup(A11,Data_Reps!A:A,Data_Reps!J:J),0) -> 0 | H11: =IFERROR(xlookup(A11,Data_Reps!A:A,Data_Reps!I:I),0) -> 0 | I11: =IFERROR(xlookup(A11,Data_Reps!A:A,Data_Reps!L:L),0) -> 0 | J11: =IFERROR(xlookup(A11,Data_Reps!A:A,Data_Reps!M:M),0) -> 0
A12: Aisha Johnson | B12: Central | C12: Commercial | D12: =IFERROR(xlookup(A12,Data_Reps!A:A,Data_Reps!D:D),0) -> 0 | E12: =IFERROR(xlookup(A12,Data_Reps!A:A,Data_Reps!E:E),0) -> 0 | F12: =IFERROR(E12/D12,0) -> 0 | G12: =IFERROR(xlookup(A12,Data_Reps!A:A,Data_Reps!J:J),0) -> 0 | H12: =IFERROR(xlookup(A12,Data_Reps!A:A,Data_Reps!I:I),0) -> 0 | I12: =IFERROR(xlookup(A12,Data_Reps!A:A,Data_Reps!L:L),0) -> 0 | J12: =IFERROR(xlookup(A12,Data_Reps!A:A,Data_Reps!M:M),0) -> 0
A13: Priya Nair | B13: West | C13: Commercial | D13: =IFERROR(xlookup(A13,Data_Reps!A:A,Data_Reps!D:D),0) -> 0 | E13: =IFERROR(xlookup(A13,Data_Reps!A:A,Data_Reps!E:E),0) -> 0 | F13: =IFERROR(E13/D13,0) -> 0 | G13: =IFERROR(xlookup(A13,Data_Reps!A:A,Data_Reps!J:J),0) -> 0 | H13: =IFERROR(xlookup(A13,Data_Reps!A:A,Data_Reps!I:I),0) -> 0 | I13: =IFERROR(xlookup(A13,Data_Reps!A:A,Data_Reps!L:L),0) -> 0 | J13: =IFERROR(xlookup(A13,Data_Reps!A:A,Data_Reps!M:M),0) -> 0
A14: Derek Walsh | B14: West | C14: Public Sector | D14: =IFERROR(xlookup(A14,Data_Reps!A:A,Data_Reps!D:D),0) -> 0 | E14: =IFERROR(xlookup(A14,Data_Reps!A:A,Data_Reps!E:E),0) -> 0 | F14: =IFERROR(E14/D14,0) -> 0 | G14: =IFERROR(xlookup(A14,Data_Reps!A:A,Data_Reps!J:J),0) -> 0 | H14: =IFERROR(xlookup(A14,Data_Reps!A:A,Data_Reps!I:I),0) -> 0 | I14: =IFERROR(xlookup(A14,Data_Reps!A:A,Data_Reps!L:L),0) -> 0 | J14: =IFERROR(xlookup(A14,Data_Reps!A:A,Data_Reps!M:M),0) -> 0
A15: Marcus Chen | B15: East | C15: Enterprise | D15: =IFERROR(xlookup(A15,Data_Reps!A:A,Data_Reps!D:D),0) -> 0 | E15: =IFERROR(xlookup(A15,Data_Reps!A:A,Data_Reps!E:E),0) -> 0 | F15: =IFERROR(E15/D15,0) -> 0 | G15: =IFERROR(xlookup(A15,Data_Reps!A:A,Data_Reps!J:J),0) -> 0 | H15: =IFERROR(xlookup(A15,Data_Reps!A:A,Data_Reps!I:I),0) -> 0 | I15: =IFERROR(xlookup(A15,Data_Reps!A:A,Data_Reps!L:L),0) -> 0 | J15: =IFERROR(xlookup(A15,Data_Reps!A:A,Data_Reps!M:M),0) -> 0
A16: Jordan Mitchell | B16: West | C16: Enterprise | D16: =IFERROR(xlookup(A16,Data_Reps!A:A,Data_Reps!D:D),0) -> 0 | E16: =IFERROR(xlookup(A16,Data_Reps!A:A,Data_Reps!E:E),0) -> 0 | F16: =IFERROR(E16/D16,0) -> 0 | G16: =IFERROR(xlookup(A16,Data_Reps!A:A,Data_Reps!J:J),0) -> 0 | H16: =IFERROR(xlookup(A16,Data_Reps!A:A,Data_Reps!I:I),0) -> 0 | I16: =IFERROR(xlookup(A16,Data_Reps!A:A,Data_Reps!L:L),0) -> 0 | J16: =IFERROR(xlookup(A16,Data_Reps!A:A,Data_Reps!M:M),0) -> 0
A17: TEAM TOTAL / AVERAGE | D17: =SUM(D5:D16) -> 0 | E17: =SUM(E5:E16) -> 0 | F17: =IFERROR(E17/D17,0) -> 0 | G17: =AVERAGE(G5:G16) -> 0 | H17: =AVERAGE(H5:H16) -> 0 | I17: =AVERAGE(I5:I16) -> 0 | J17: =AVERAGE(J5:J16) -> 0
A19: B | Month-End Close — Actual vs. Plan Variance (Q4 2024) [AVERAGEIFS from Data_Monthly]
A20: Month | B20: Rep Name | C20: Region | D20: Plan Revenue | E20: Actual Revenue | F20: Variance $ | G20: Variance % | H20: Actual Disc% | I20: Actual GM% | J20: Status
A21: 2024-10 | B21: Aisha Johnson | C21: Central | D21: =IFERROR(AVERAGEIFS(Data_Monthly!E:E,Data_Monthly!B:B,B21,Data_Monthly!C:C,A21),0) -> 0 | E21: =IFERROR(AVERAGEIFS(Data_Monthly!D:D,Data_Monthly!B:B,B21,Data_Monthly!C:C,A21),0) -> 0 | F21: =E21-D21 -> 0 | G21: =IFERROR(F21/D21,0) -> 0 | H21: =IFERROR(AVERAGEIFS(Data_Monthly!H:H,Data_Monthly!B:B,B21,Data_Monthly!C:C,A21),0) -> 0 | I21: =IFERROR(AVERAGEIFS(Data_Monthly!I:I,Data_Monthly!B:B,B21,Data_Monthly!C:C,A21),0) -> 0 | J21: =IF(F21>=0,"✓ Beat","✗ Miss") -> ✓ Beat
A22: 2024-10 | B22: Carlos Rivera | C22: Central | D22: =IFERROR(AVERAGEIFS(Data_Monthly!E:E,Data_Monthly!B:B,B22,Data_Monthly!C:C,A22),0) -> 0 | E22: =IFERROR(AVERAGEIFS(Data_Monthly!D:D,Data_Monthly!B:B,B22,Data_Monthly!C:C,A22),0) -> 0 | F22: =E22-D22 -> 0 | G22: =IFERROR(F22/D22,0) -> 0 | H22: =IFERROR(AVERAGEIFS(Data_Monthly!H:H,Data_Monthly!B:B,B22,Data_Monthly!C:C,A22),0) -> 0 | I22: =IFERROR(AVERAGEIFS(Data_Monthly!I:I,Data_Monthly!B:B,B22,Data_Monthly!C:C,A22),0) -> 0 | J22: =IF(F22>=0,"✓ Beat","✗ Miss") -> ✓ Beat
A23: 2024-10 | B23: Derek Walsh | C23: West | D23: =IFERROR(AVERAGEIFS(Data_Monthly!E:E,Data_Monthly!B:B,B23,Data_Monthly!C:C,A23),0) -> 0 | E23: =IFERROR(AVERAGEIFS(Data_Monthly!D:D,Data_Monthly!B:B,B23,Data_Monthly!C:C,A23),0) -> 0 | F23: =E23-D23 -> 0 | G23: =IFERROR(F23/D23,0) -> 0 | H23: =IFERROR(AVERAGEIFS(Data_Monthly!H:H,Data_Monthly!B:B,B23,Data_Monthly!C:C,A23),0) -> 0 | I23: =IFERROR(AVERAGEIFS(Data_Monthly!I:I,Data_Monthly!B:B,B23,Data_Monthly!C:C,A23),0) -> 0 | J23: =IF(F23>=0,"✓ Beat","✗ Miss") -> ✓ Beat
A24: 2024-10 | B24: Jordan Mitchell | C24: West | D24: =IFERROR(AVERAGEIFS(Data_Monthly!E:E,Data_Monthly!B:B,B24,Data_Monthly!C:C,A24),0) -> 0 | E24: =IFERROR(AVERAGEIFS(Data_Monthly!D:D,Data_Monthly!B:B,B24,Data_Monthly!C:C,A24),0) -> 0 | F24: =E24-D24 -> 0 | G24: =IFERROR(F24/D24,0) -> 0 | H24: =IFERROR(AVERAGEIFS(Data_Monthly!H:H,Data_Monthly!B:B,B24,Data_Monthly!C:C,A24),0) -> 0 | I24: =IFERROR(AVERAGEIFS(Data_Monthly!I:I,Data_Monthly!B:B,B24,Data_Monthly!C:C,A24),0) -> 0 | J24: =IF(F24>=0,"✓ Beat","✗ Miss") -> ✓ Beat
A25: 2024-10 | B25: Kenji Tanaka | C25: South | D25: =IFERROR(AVERAGEIFS(Data_Monthly!E:E,Data_Monthly!B:B,B25,Data_Monthly!C:C,A25),0) -> 0 | E25: =IFERROR(AVERAGEIFS(Data_Monthly!D:D,Data_Monthly!B:B,B25,Data_Monthly!C:C,A25),0) -> 0 | F25: =E25-D25 -> 0 | G25: =IFERROR(F25/D25,0) -> 0 | H25: =IFERROR(AVERAGEIFS(Data_Monthly!H:H,Data_Monthly!B:B,B25,Data_Monthly!C:C,A25),0) -> 0 | I25: =IFERROR(AVERAGEIFS(Data_Monthly!I:I,Data_Monthly!B:B,B25,Data_Monthly!C:C,A25),0) -> 0 | J25: =IF(F25>=0,"✓ Beat","✗ Miss") -> ✓ Beat
A26: 2024-10 | B26: Marcus Chen | C26: East | D26: =IFERROR(AVERAGEIFS(Data_Monthly!E:E,Data_Monthly!B:B,B26,Data_Monthly!C:C,A26),0) -> 0 | E26: =IFERROR(AVERAGEIFS(Data_Monthly!D:D,Data_Monthly!B:B,B26,Data_Monthly!C:C,A26),0) -> 0 | F26: =E26-D26 -> 0 | G26: =IFERROR(F26/D26,0) -> 0 | H26: =IFERROR(AVERAGEIFS(Data_Monthly!H:H,Data_Monthly!B:B,B26,Data_Monthly!C:C,A26),0) -> 0 | I26: =IFERROR(AVERAGEIFS(Data_Monthly!I:I,Data_Monthly!B:B,B26,Data_Monthly!C:C,A26),0) -> 0 | J26: =IF(F26>=0,"✓ Beat","✗ Miss") -> ✓ Beat
A27: 2024-10 | B27: Mei-Lin Park | C27: East | D27: =IFERROR(AVERAGEIFS(Data_Monthly!E:E,Data_Monthly!B:B,B27,Data_Monthly!C:C,A27),0) -> 0 | E27: =IFERROR(AVERAGEIFS(Data_Monthly!D:D,Data_Monthly!B:B,B27,Data_Monthly!C:C,A27),0) -> 0 | F27: =E27-D27 -> 0 | G27: =IFERROR(F27/D27,0) -> 0 | H27: =IFERROR(AVERAGEIFS(Data_Monthly!H:H,Data_Monthly!B:B,B27,Data_Monthly!C:C,A27),0) -> 0 | I27: =IFERROR(AVERAGEIFS(Data_Monthly!I:I,Data_Monthly!B:B,B27,Data_Monthly!C:C,A27),0) -> 0 | J27: =IF(F27>=0,"✓ Beat","✗ Miss") -> ✓ Beat
A28: 2024-10 | B28: Natalie Frost | C28: South | D28: =IFERROR(AVERAGEIFS(Data_Monthly!E:E,Data_Monthly!B:B,B28,Data_Monthly!C:C,A28),0) -> 0 | E28: =IFERROR(AVERAGEIFS(Data_Monthly!D:D,Data_Monthly!B:B,B28,Data_Monthly!C:C,A28),0) -> 0 | F28: =E28-D28 -> 0 | G28: =IFERROR(F28/D28,0) -> 0 | H28: =IFERROR(AVERAGEIFS(Data_Monthly!H:H,Data_Monthly!B:B,B28,Data_Monthly!C:C,A28),0) -> 0 | I28: =IFERROR(AVERAGEIFS(Data_Monthly!I:I,Data_Monthly!B:B,B28,Data_Monthly!C:C,A28),0) -> 0 | J28: =IF(F28>=0,"✓ Beat","✗ Miss") -> ✓ Beat
A29: 2024-10 | B29: Priya Nair | C29: West | D29: =IFERROR(AVERAGEIFS(Data_Monthly!E:E,Data_Monthly!B:B,B29,Data_Monthly!C:C,A29),0) -> 0 | E29: =IFERROR(AVERAGEIFS(Data_Monthly!D:D,Data_Monthly!B:B,B29,Data_Monthly!C:C,A29),0) -> 0 | F29: =E29-D29 -> 0 | G29: =IFERROR(F29/D29,0) -> 0 | H29: =IFERROR(AVERAGEIFS(Data_Monthly!H:H,Data_Monthly!B:B,B29,Data_Monthly!C:C,A29),0) -> 0 | I29: =IFERROR(AVERAGEIFS(Data_Monthly!I:I,Data_Monthly!B:B,B29,Data_Monthly!C:C,A29),0) -> 0 | J29: =IF(F29>=0,"✓ Beat","✗ Miss") -> ✓ Beat
A30: 2024-10 | B30: Rachel Okafor | C30: South | D30: =IFERROR(AVERAGEIFS(Data_Monthly!E:E,Data_Monthly!B:B,B30,Data_Monthly!C:C,A30),0) -> 0 | E30: =IFERROR(AVERAGEIFS(Data_Monthly!D:D,Data_Monthly!B:B,B30,Data_Monthly!C:C,A30),0) -> 0 | F30: =E30-D30 -> 0 | G30: =IFERROR(F30/D30,0) -> 0 | H30: =IFERROR(AVERAGEIFS(Data_Monthly!H:H,Data_Monthly!B:B,B30,Data_Monthly!C:C,A30),0) -> 0 | I30: =IFERROR(AVERAGEIFS(Data_Monthly!I:I,Data_Monthly!B:B,B30,Data_Monthly!C:C,A30),0) -> 0 | J30: =IF(F30>=0,"✓ Beat","✗ Miss") -> ✓ Beat
A31: 2024-10 | B31: Sofia Delgado | C31: East | D31: =IFERROR(AVERAGEIFS(Data_Monthly!E:E,Data_Monthly!B:B,B31,Data_Monthly!C:C,A31),0) -> 0 | E31: =IFERROR(AVERAGEIFS(Data_Monthly!D:D,Data_Monthly!B:B,B31,Data_Monthly!C:C,A31),0) -> 0 | F31: =E31-D31 -> 0 | G31: =IFERROR(F31/D31,0) -> 0 | H31: =IFERROR(AVERAGEIFS(Data_Monthly!H:H,Data_Monthly!B:B,B31,Data_Monthly!C:C,A31),0) -> 0 | I31: =IFERROR(AVERAGEIFS(Data_Monthly!I:I,Data_Monthly!B:B,B31,Data_Monthly!C:C,A31),0) -> 0 | J31: =IF(F31>=0,"✓ Beat","✗ Miss") -> ✓ Beat
A32: 2024-10 | B32: Tyler Brooks | C32: Central | D32: =IFERROR(AVERAGEIFS(Data_Monthly!E:E,Data_Monthly!B:B,B32,Data_Monthly!C:C,A32),0) -> 0 | E32: =IFERROR(AVERAGEIFS(Data_Monthly!D:D,Data_Monthly!B:B,B32,Data_Monthly!C:C,A32),0) -> 0 | F32: =E32-D32 -> 0 | G32: =IFERROR(F32/D32,0) -> 0 | H32: =IFERROR(AVERAGEIFS(Data_Monthly!H:H,Data_Monthly!B:B,B32,Data_Monthly!C:C,A32),0) -> 0 | I32: =IFERROR(AVERAGEIFS(Data_Monthly!I:I,Data_Monthly!B:B,B32,Data_Monthly!C:C,A32),0) -> 0 | J32: =IF(F32>=0,"✓ Beat","✗ Miss") -> ✓ Beat
... A56: 2024-12 | B56: Tyler Brooks | C56: Central | D56: =IFERROR(AVERAGEIFS(Data_Monthly!E:E,Data_Monthly!B:B,B56,Data_Monthly!C:C,A56),0) -> 0 | E56: =IFERROR(AVERAGEIFS(Data_Monthly!D:D,Data_Monthly!B:B,B56,Data_Monthly!C:C,A56),0) -> 0 | F56: =E56-D56 -> 0 | G56: =IFERROR(F56/D56,0) -> 0 | H56: =IFERROR(AVERAGEIFS(Data_Monthly!H:H,Data_Monthly!B:B,B56,Data_Monthly!C:C,A56),0) -> 0 | I56: =IFERROR(AVERAGEIFS(Data_Monthly!I:I,Data_Monthly!B:B,B56,Data_Monthly!C:C,A56),0) -> 0 | J56: =IF(F56>=0,"✓ Beat","✗ Miss") -> ✓ Beat
